2025-06-11 17:20:31 - main-thread - root - INFO - Запуск застосунку 'Юридичний асистент'.
2025-06-11 17:20:31 - main-thread - root - INFO - Ініціалізація пошукового рушія...
2025-06-11 17:20:31 - main-thread - root - INFO - Дані успішно завантажено з documents.pkl.
2025-06-11 17:20:31 - main-thread - root - INFO - Пошуковий рушій успішно ініціалізовано.
2025-06-11 17:20:32 - main-thread - root - INFO - Запуск веб-інтерфейсу Gradio...
2025-06-11 17:22:14 - main-thread - root - INFO - Застосунок 'Юридичний асистент' завершив роботу.
2025-06-11 17:22:17 - main-thread - root - INFO - Запуск застосунку 'Юридичний асистент'.
2025-06-11 17:22:17 - main-thread - root - INFO - Ініціалізація пошукового рушія...
2025-06-11 17:22:17 - main-thread - root - INFO - Дані успішно завантажено з documents.pkl.
2025-06-11 17:22:17 - main-thread - root - INFO - Пошуковий рушій успішно ініціалізовано.
2025-06-11 17:22:17 - main-thread - root - INFO - Запуск веб-інтерфейсу Gradio...
2025-06-11 17:24:20 - main-thread - root - INFO - Застосунок 'Юридичний асистент' завершив роботу.
2025-06-11 17:24:24 - main-thread - pymorphy3.opencorpora_dict.wrapper - INFO - Loading dictionaries from E:\Users\Егор\PycharmProjects\andrewtest1\.venv\lib\site-packages\pymorphy3_dicts_ru\data
2025-06-11 17:24:24 - main-thread - pymorphy3.opencorpora_dict.wrapper - INFO - format: 2.4, revision: 417150, updated: 2022-01-08T22:09:24.565962
2025-06-11 17:24:24 - main-thread - __main__ - INFO - Запуск застосунку 'Юридичний асистент'.
2025-06-11 17:24:24 - main-thread - __main__ - INFO - Ініціалізація пошукового рушія...
2025-06-11 17:24:24 - main-thread - __main__ - INFO - Дані успішно завантажено з documents.pkl.
2025-06-11 17:24:24 - main-thread - __main__ - INFO - Пошуковий рушій успішно ініціалізовано.
2025-06-11 17:24:24 - main-thread - __main__ - INFO - Запуск веб-інтерфейсу Gradio...
2025-06-11 17:24:24 - main-thread - httpx - INFO - HTTP Request: GET http://127.0.0.1:7860/gradio_api/startup-events "HTTP/1.1 200 OK"
2025-06-11 17:24:24 - main-thread - httpx - INFO - HTTP Request: HEAD http://127.0.0.1:7860/ "HTTP/1.1 200 OK"
2025-06-11 17:24:26 - main-thread - httpx - INFO - HTTP Request: GET https://api.gradio.app/pkg-version "HTTP/1.1 200 OK"
2025-06-11 17:43:58 - main-thread - __main__ - INFO - Застосунок 'Юридичний асистент' завершив роботу.
2025-06-11 17:45:03 - main-thread - pymorphy3.opencorpora_dict.wrapper - INFO - Loading dictionaries from E:\Users\Егор\PycharmProjects\andrewtest1\.venv\lib\site-packages\pymorphy3_dicts_ru\data
2025-06-11 17:45:03 - main-thread - pymorphy3.opencorpora_dict.wrapper - INFO - format: 2.4, revision: 417150, updated: 2022-01-08T22:09:24.565962
2025-06-11 17:45:03 - main-thread - __main__ - INFO - Запуск застосунку 'Юридичний асистент'.
2025-06-11 17:45:03 - main-thread - __main__ - INFO - Ініціалізація пошукового рушія...
2025-06-11 17:45:03 - main-thread - __main__ - INFO - Дані успішно завантажено з documents.pkl.
2025-06-11 17:45:03 - main-thread - __main__ - INFO - Пошуковий рушій успішно ініціалізовано.
2025-06-11 17:45:03 - main-thread - __main__ - INFO - Запуск веб-інтерфейсу Gradio...
2025-06-11 17:45:03 - main-thread - httpx - INFO - HTTP Request: GET http://127.0.0.1:7860/gradio_api/startup-events "HTTP/1.1 200 OK"
2025-06-11 17:45:03 - main-thread - httpx - INFO - HTTP Request: HEAD http://127.0.0.1:7860/ "HTTP/1.1 200 OK"
2025-06-11 17:45:04 - main-thread - httpx - INFO - HTTP Request: GET https://api.gradio.app/pkg-version "HTTP/1.1 200 OK"
2025-06-11 17:46:06 - req-ce39df04 - __main__ - INFO - Отримано новий запит від користувача: ''
2025-06-11 17:46:08 - req-ce39df04 - __main__ - ERROR - Невідома помилка при генерації відповіді. ID: 0ce8de60-2c0d-4559-94c5-9d60ff9cd944. Запит: ''.
Traceback (most recent call last):
  File "E:\Users\Егор\PycharmProjects\andrewtest1\app.py", line 258, in generate_answer
    res = ollama.chat(
  File "E:\Users\Егор\PycharmProjects\andrewtest1\.venv\lib\site-packages\ollama\_client.py", line 342, in chat
    return self._request(
  File "E:\Users\Егор\PycharmProjects\andrewtest1\.venv\lib\site-packages\ollama\_client.py", line 180, in _request
    return cls(**self._request_raw(*args, **kwargs).json())
  File "E:\Users\Егор\PycharmProjects\andrewtest1\.venv\lib\site-packages\ollama\_client.py", line 126, in _request_raw
    raise ConnectionError(CONNECTION_ERROR_MESSAGE) from None
ConnectionError: Failed to connect to Ollama. Please check that Ollama is downloaded, running and accessible. https://ollama.com/download
2025-06-11 17:58:45 - main-thread - pymorphy3.opencorpora_dict.wrapper - INFO - Loading dictionaries from E:\Users\Егор\PycharmProjects\andrewtest1\.venv\lib\site-packages\pymorphy3_dicts_ru\data
2025-06-11 17:58:45 - main-thread - pymorphy3.opencorpora_dict.wrapper - INFO - format: 2.4, revision: 417150, updated: 2022-01-08T22:09:24.565962
2025-06-11 17:58:45 - main-thread - app - INFO - Початок процесу обробки даних...
2025-06-11 17:58:45 - main-thread - app - INFO - Початок збору даних з 3 джерел.
2025-06-11 17:58:45 - main-thread - app - ERROR - Помилка при зборі даних. ID помилки: 87c8fb37-1d1f-49b6-ad3d-e5bac2c8a812. URL: https://zakon.rada.gov.ua/laws/show/2341-14#Text.
Traceback (most recent call last):
  File "E:\Users\Егор\PycharmProjects\andrewtest1\.venv\lib\site-packages\urllib3\connectionpool.py", line 787, in urlopen
    response = self._make_request(
  File "E:\Users\Егор\PycharmProjects\andrewtest1\.venv\lib\site-packages\urllib3\connectionpool.py", line 488, in _make_request
    raise new_e
  File "E:\Users\Егор\PycharmProjects\andrewtest1\.venv\lib\site-packages\urllib3\connectionpool.py", line 464, in _make_request
    self._validate_conn(conn)
  File "E:\Users\Егор\PycharmProjects\andrewtest1\.venv\lib\site-packages\urllib3\connectionpool.py", line 1093, in _validate_conn
    conn.connect()
  File "E:\Users\Егор\PycharmProjects\andrewtest1\.venv\lib\site-packages\urllib3\connection.py", line 741, in connect
    sock_and_verified = _ssl_wrap_socket_and_match_hostname(
  File "E:\Users\Егор\PycharmProjects\andrewtest1\.venv\lib\site-packages\urllib3\connection.py", line 920, in _ssl_wrap_socket_and_match_hostname
    ssl_sock = ssl_wrap_socket(
  File "E:\Users\Егор\PycharmProjects\andrewtest1\.venv\lib\site-packages\urllib3\util\ssl_.py", line 480, in ssl_wrap_socket
    ssl_sock = _ssl_wrap_socket_impl(sock, context, tls_in_tls, server_hostname)
  File "E:\Users\Егор\PycharmProjects\andrewtest1\.venv\lib\site-packages\urllib3\util\ssl_.py", line 524, in _ssl_wrap_socket_impl
    return ssl_context.wrap_socket(sock, server_hostname=server_hostname)
  File "E:\Users\Егор\AppData\Local\Programs\Python\Python310\lib\ssl.py", line 513, in wrap_socket
    return self.sslsocket_class._create(
  File "E:\Users\Егор\AppData\Local\Programs\Python\Python310\lib\ssl.py", line 1071, in _create
    self.do_handshake()
  File "E:\Users\Егор\AppData\Local\Programs\Python\Python310\lib\ssl.py", line 1342, in do_handshake
    self._sslobj.do_handshake()
ConnectionResetError: [WinError 10054] Удаленный хост принудительно разорвал существующее подключение

During handling of the above exception, another exception occurred:

Traceback (most recent call last):
  File "E:\Users\Егор\PycharmProjects\andrewtest1\.venv\lib\site-packages\requests\adapters.py", line 667, in send
    resp = conn.urlopen(
  File "E:\Users\Егор\PycharmProjects\andrewtest1\.venv\lib\site-packages\urllib3\connectionpool.py", line 841, in urlopen
    retries = retries.increment(
  File "E:\Users\Егор\PycharmProjects\andrewtest1\.venv\lib\site-packages\urllib3\util\retry.py", line 474, in increment
    raise reraise(type(error), error, _stacktrace)
  File "E:\Users\Егор\PycharmProjects\andrewtest1\.venv\lib\site-packages\urllib3\util\util.py", line 38, in reraise
    raise value.with_traceback(tb)
  File "E:\Users\Егор\PycharmProjects\andrewtest1\.venv\lib\site-packages\urllib3\connectionpool.py", line 787, in urlopen
    response = self._make_request(
  File "E:\Users\Егор\PycharmProjects\andrewtest1\.venv\lib\site-packages\urllib3\connectionpool.py", line 488, in _make_request
    raise new_e
  File "E:\Users\Егор\PycharmProjects\andrewtest1\.venv\lib\site-packages\urllib3\connectionpool.py", line 464, in _make_request
    self._validate_conn(conn)
  File "E:\Users\Егор\PycharmProjects\andrewtest1\.venv\lib\site-packages\urllib3\connectionpool.py", line 1093, in _validate_conn
    conn.connect()
  File "E:\Users\Егор\PycharmProjects\andrewtest1\.venv\lib\site-packages\urllib3\connection.py", line 741, in connect
    sock_and_verified = _ssl_wrap_socket_and_match_hostname(
  File "E:\Users\Егор\PycharmProjects\andrewtest1\.venv\lib\site-packages\urllib3\connection.py", line 920, in _ssl_wrap_socket_and_match_hostname
    ssl_sock = ssl_wrap_socket(
  File "E:\Users\Егор\PycharmProjects\andrewtest1\.venv\lib\site-packages\urllib3\util\ssl_.py", line 480, in ssl_wrap_socket
    ssl_sock = _ssl_wrap_socket_impl(sock, context, tls_in_tls, server_hostname)
  File "E:\Users\Егор\PycharmProjects\andrewtest1\.venv\lib\site-packages\urllib3\util\ssl_.py", line 524, in _ssl_wrap_socket_impl
    return ssl_context.wrap_socket(sock, server_hostname=server_hostname)
  File "E:\Users\Егор\AppData\Local\Programs\Python\Python310\lib\ssl.py", line 513, in wrap_socket
    return self.sslsocket_class._create(
  File "E:\Users\Егор\AppData\Local\Programs\Python\Python310\lib\ssl.py", line 1071, in _create
    self.do_handshake()
  File "E:\Users\Егор\AppData\Local\Programs\Python\Python310\lib\ssl.py", line 1342, in do_handshake
    self._sslobj.do_handshake()
urllib3.exceptions.ProtocolError: ('Connection aborted.', ConnectionResetError(10054, 'Удаленный хост принудительно разорвал существующее подключение', None, 10054, None))

During handling of the above exception, another exception occurred:

Traceback (most recent call last):
  File "E:\Users\Егор\PycharmProjects\andrewtest1\app.py", line 119, in scrape_legal_data
    resp = requests.get(url, headers=REQUEST_HEADERS, timeout=10)
  File "E:\Users\Егор\PycharmProjects\andrewtest1\.venv\lib\site-packages\requests\api.py", line 73, in get
    return request("get", url, params=params, **kwargs)
  File "E:\Users\Егор\PycharmProjects\andrewtest1\.venv\lib\site-packages\requests\api.py", line 59, in request
    return session.request(method=method, url=url, **kwargs)
  File "E:\Users\Егор\PycharmProjects\andrewtest1\.venv\lib\site-packages\requests\sessions.py", line 589, in request
    resp = self.send(prep, **send_kwargs)
  File "E:\Users\Егор\PycharmProjects\andrewtest1\.venv\lib\site-packages\requests\sessions.py", line 703, in send
    r = adapter.send(request, **kwargs)
  File "E:\Users\Егор\PycharmProjects\andrewtest1\.venv\lib\site-packages\requests\adapters.py", line 682, in send
    raise ConnectionError(err, request=request)
requests.exceptions.ConnectionError: ('Connection aborted.', ConnectionResetError(10054, 'Удаленный хост принудительно разорвал существующее подключение', None, 10054, None))
2025-06-11 17:58:46 - main-thread - app - INFO - Успішно завантажено та оброблено: https://zakon.rada.gov.ua/laws/show/80731-10#Text
2025-06-11 17:58:47 - main-thread - app - INFO - Успішно завантажено та оброблено: https://zakon.rada.gov.ua/laws/show/80732-10#Text
2025-06-11 17:58:47 - main-thread - app - INFO - Збір даних завершено. Отримано 2 документів.
2025-06-11 17:58:47 - main-thread - app - INFO - Початок розбиття на сегменти...
2025-06-11 18:00:36 - main-thread - pymorphy3.opencorpora_dict.wrapper - INFO - Loading dictionaries from E:\Users\Егор\PycharmProjects\andrewtest1\.venv\lib\site-packages\pymorphy3_dicts_ru\data
2025-06-11 18:00:36 - main-thread - pymorphy3.opencorpora_dict.wrapper - INFO - format: 2.4, revision: 417150, updated: 2022-01-08T22:09:24.565962
2025-06-11 18:00:36 - main-thread - app - INFO - Початок процесу обробки даних...
2025-06-11 18:00:36 - main-thread - app - INFO - Початок збору даних з 3 джерел.
2025-06-11 18:00:36 - main-thread - app - INFO - Успішно завантажено та оброблено: https://zakon.rada.gov.ua/laws/show/2341-14#Text
2025-06-11 18:00:36 - main-thread - app - INFO - Успішно завантажено та оброблено: https://zakon.rada.gov.ua/laws/show/80731-10#Text
2025-06-11 18:00:36 - main-thread - app - ERROR - Помилка при зборі даних. ID помилки: 293e6154-3fca-42d2-9b97-feddee132533. URL: https://zakon.rada.gov.ua/laws/show/80732-10#Text.
Traceback (most recent call last):
  File "E:\Users\Егор\PycharmProjects\andrewtest1\.venv\lib\site-packages\urllib3\connectionpool.py", line 787, in urlopen
    response = self._make_request(
  File "E:\Users\Егор\PycharmProjects\andrewtest1\.venv\lib\site-packages\urllib3\connectionpool.py", line 488, in _make_request
    raise new_e
  File "E:\Users\Егор\PycharmProjects\andrewtest1\.venv\lib\site-packages\urllib3\connectionpool.py", line 464, in _make_request
    self._validate_conn(conn)
  File "E:\Users\Егор\PycharmProjects\andrewtest1\.venv\lib\site-packages\urllib3\connectionpool.py", line 1093, in _validate_conn
    conn.connect()
  File "E:\Users\Егор\PycharmProjects\andrewtest1\.venv\lib\site-packages\urllib3\connection.py", line 741, in connect
    sock_and_verified = _ssl_wrap_socket_and_match_hostname(
  File "E:\Users\Егор\PycharmProjects\andrewtest1\.venv\lib\site-packages\urllib3\connection.py", line 920, in _ssl_wrap_socket_and_match_hostname
    ssl_sock = ssl_wrap_socket(
  File "E:\Users\Егор\PycharmProjects\andrewtest1\.venv\lib\site-packages\urllib3\util\ssl_.py", line 480, in ssl_wrap_socket
    ssl_sock = _ssl_wrap_socket_impl(sock, context, tls_in_tls, server_hostname)
  File "E:\Users\Егор\PycharmProjects\andrewtest1\.venv\lib\site-packages\urllib3\util\ssl_.py", line 524, in _ssl_wrap_socket_impl
    return ssl_context.wrap_socket(sock, server_hostname=server_hostname)
  File "E:\Users\Егор\AppData\Local\Programs\Python\Python310\lib\ssl.py", line 513, in wrap_socket
    return self.sslsocket_class._create(
  File "E:\Users\Егор\AppData\Local\Programs\Python\Python310\lib\ssl.py", line 1071, in _create
    self.do_handshake()
  File "E:\Users\Егор\AppData\Local\Programs\Python\Python310\lib\ssl.py", line 1342, in do_handshake
    self._sslobj.do_handshake()
ConnectionResetError: [WinError 10054] Удаленный хост принудительно разорвал существующее подключение

During handling of the above exception, another exception occurred:

Traceback (most recent call last):
  File "E:\Users\Егор\PycharmProjects\andrewtest1\.venv\lib\site-packages\requests\adapters.py", line 667, in send
    resp = conn.urlopen(
  File "E:\Users\Егор\PycharmProjects\andrewtest1\.venv\lib\site-packages\urllib3\connectionpool.py", line 841, in urlopen
    retries = retries.increment(
  File "E:\Users\Егор\PycharmProjects\andrewtest1\.venv\lib\site-packages\urllib3\util\retry.py", line 474, in increment
    raise reraise(type(error), error, _stacktrace)
  File "E:\Users\Егор\PycharmProjects\andrewtest1\.venv\lib\site-packages\urllib3\util\util.py", line 38, in reraise
    raise value.with_traceback(tb)
  File "E:\Users\Егор\PycharmProjects\andrewtest1\.venv\lib\site-packages\urllib3\connectionpool.py", line 787, in urlopen
    response = self._make_request(
  File "E:\Users\Егор\PycharmProjects\andrewtest1\.venv\lib\site-packages\urllib3\connectionpool.py", line 488, in _make_request
    raise new_e
  File "E:\Users\Егор\PycharmProjects\andrewtest1\.venv\lib\site-packages\urllib3\connectionpool.py", line 464, in _make_request
    self._validate_conn(conn)
  File "E:\Users\Егор\PycharmProjects\andrewtest1\.venv\lib\site-packages\urllib3\connectionpool.py", line 1093, in _validate_conn
    conn.connect()
  File "E:\Users\Егор\PycharmProjects\andrewtest1\.venv\lib\site-packages\urllib3\connection.py", line 741, in connect
    sock_and_verified = _ssl_wrap_socket_and_match_hostname(
  File "E:\Users\Егор\PycharmProjects\andrewtest1\.venv\lib\site-packages\urllib3\connection.py", line 920, in _ssl_wrap_socket_and_match_hostname
    ssl_sock = ssl_wrap_socket(
  File "E:\Users\Егор\PycharmProjects\andrewtest1\.venv\lib\site-packages\urllib3\util\ssl_.py", line 480, in ssl_wrap_socket
    ssl_sock = _ssl_wrap_socket_impl(sock, context, tls_in_tls, server_hostname)
  File "E:\Users\Егор\PycharmProjects\andrewtest1\.venv\lib\site-packages\urllib3\util\ssl_.py", line 524, in _ssl_wrap_socket_impl
    return ssl_context.wrap_socket(sock, server_hostname=server_hostname)
  File "E:\Users\Егор\AppData\Local\Programs\Python\Python310\lib\ssl.py", line 513, in wrap_socket
    return self.sslsocket_class._create(
  File "E:\Users\Егор\AppData\Local\Programs\Python\Python310\lib\ssl.py", line 1071, in _create
    self.do_handshake()
  File "E:\Users\Егор\AppData\Local\Programs\Python\Python310\lib\ssl.py", line 1342, in do_handshake
    self._sslobj.do_handshake()
urllib3.exceptions.ProtocolError: ('Connection aborted.', ConnectionResetError(10054, 'Удаленный хост принудительно разорвал существующее подключение', None, 10054, None))

During handling of the above exception, another exception occurred:

Traceback (most recent call last):
  File "E:\Users\Егор\PycharmProjects\andrewtest1\app.py", line 119, in scrape_legal_data
    resp = requests.get(url, headers=REQUEST_HEADERS, timeout=10)
  File "E:\Users\Егор\PycharmProjects\andrewtest1\.venv\lib\site-packages\requests\api.py", line 73, in get
    return request("get", url, params=params, **kwargs)
  File "E:\Users\Егор\PycharmProjects\andrewtest1\.venv\lib\site-packages\requests\api.py", line 59, in request
    return session.request(method=method, url=url, **kwargs)
  File "E:\Users\Егор\PycharmProjects\andrewtest1\.venv\lib\site-packages\requests\sessions.py", line 589, in request
    resp = self.send(prep, **send_kwargs)
  File "E:\Users\Егор\PycharmProjects\andrewtest1\.venv\lib\site-packages\requests\sessions.py", line 703, in send
    r = adapter.send(request, **kwargs)
  File "E:\Users\Егор\PycharmProjects\andrewtest1\.venv\lib\site-packages\requests\adapters.py", line 682, in send
    raise ConnectionError(err, request=request)
requests.exceptions.ConnectionError: ('Connection aborted.', ConnectionResetError(10054, 'Удаленный хост принудительно разорвал существующее подключение', None, 10054, None))
2025-06-11 18:00:36 - main-thread - app - INFO - Збір даних завершено. Отримано 2 документів.
2025-06-11 18:00:36 - main-thread - app - INFO - Початок розбиття на сегменти...
2025-06-11 18:05:09 - main-thread - pymorphy3.opencorpora_dict.wrapper - INFO - Loading dictionaries from E:\Users\Егор\PycharmProjects\andrewtest1\.venv\lib\site-packages\pymorphy3_dicts_ru\data
2025-06-11 18:05:09 - main-thread - pymorphy3.opencorpora_dict.wrapper - INFO - format: 2.4, revision: 417150, updated: 2022-01-08T22:09:24.565962
2025-06-11 18:05:09 - main-thread - app - INFO - Початок процесу обробки даних...
2025-06-11 18:05:09 - main-thread - app - INFO - Початок збору даних з 3 джерел.
2025-06-11 18:05:09 - main-thread - app - INFO - Успішно завантажено та оброблено: https://zakon.rada.gov.ua/laws/show/2341-14#Text
2025-06-11 18:05:09 - main-thread - app - INFO - Успішно завантажено та оброблено: https://zakon.rada.gov.ua/laws/show/80731-10#Text
2025-06-11 18:05:10 - main-thread - app - INFO - Успішно завантажено та оброблено: https://zakon.rada.gov.ua/laws/show/80732-10#Text
2025-06-11 18:05:10 - main-thread - app - INFO - Збір даних завершено. Отримано 3 документів.
2025-06-11 18:05:10 - main-thread - app - INFO - Початок розбиття на сегменти...
2025-06-11 18:07:06 - main-thread - pymorphy3.opencorpora_dict.wrapper - INFO - Loading dictionaries from E:\Users\Егор\PycharmProjects\andrewtest1\.venv\lib\site-packages\pymorphy3_dicts_ru\data
2025-06-11 18:07:06 - main-thread - pymorphy3.opencorpora_dict.wrapper - INFO - format: 2.4, revision: 417150, updated: 2022-01-08T22:09:24.565962
2025-06-11 18:07:06 - main-thread - app - INFO - Початок процесу обробки даних...
2025-06-11 18:07:06 - main-thread - app - INFO - Початок збору даних з 3 джерел.
2025-06-11 18:07:06 - main-thread - app - INFO - Успішно завантажено та оброблено: https://zakon.rada.gov.ua/laws/show/2341-14#Text
2025-06-11 18:07:06 - main-thread - app - INFO - Успішно завантажено та оброблено: https://zakon.rada.gov.ua/laws/show/80731-10#Text
2025-06-11 18:07:08 - main-thread - app - INFO - Успішно завантажено та оброблено: https://zakon.rada.gov.ua/laws/show/80732-10#Text
2025-06-11 18:07:08 - main-thread - app - INFO - Збір даних завершено. Отримано 3 документів.
2025-06-11 18:07:08 - main-thread - app - INFO - Початок розбиття на сегменти...
2025-06-11 18:08:18 - main-thread - pymorphy3.opencorpora_dict.wrapper - INFO - Loading dictionaries from E:\Users\Егор\PycharmProjects\andrewtest1\.venv\lib\site-packages\pymorphy3_dicts_ru\data
2025-06-11 18:08:18 - main-thread - pymorphy3.opencorpora_dict.wrapper - INFO - format: 2.4, revision: 417150, updated: 2022-01-08T22:09:24.565962
2025-06-11 18:08:18 - main-thread - app - INFO - Початок процесу обробки даних...
2025-06-11 18:08:18 - main-thread - app - INFO - Початок збору даних з 3 джерел.
2025-06-11 18:08:18 - main-thread - app - INFO - Успішно завантажено та оброблено: https://zakon.rada.gov.ua/laws/show/2341-14#Text
2025-06-11 18:08:18 - main-thread - app - INFO - Успішно завантажено та оброблено: https://zakon.rada.gov.ua/laws/show/80731-10#Text
2025-06-11 18:08:18 - main-thread - app - INFO - Успішно завантажено та оброблено: https://zakon.rada.gov.ua/laws/show/80732-10#Text
2025-06-11 18:08:18 - main-thread - app - INFO - Збір даних завершено. Отримано 3 документів.
2025-06-11 18:08:18 - main-thread - app - INFO - Початок розбиття на сегменти...
